Workbook
Name K: Project_Page_5_RP!$P$22

Sheet Data
B1: Asset 1 | C1: Asset 2 | D1: Asset3 | E1: Asset 4 | F1: Asset 5 | H1: =COUNT(B2:B121) -> 120
A2: 38016 | B2: 0.006265643 | C2: 0.034770515 | D2: 0.032609824 | E2: 0.0064599983 | F2: 0.011827397
A3: 38044 | B3: 0.0084282173 | C3: -0.032526882 | D3: 0.083965425 | E3: 0.019989996 | F3: 0.023758424
A4: 38077 | B4: 0.0043830411 | C4: -0.026674076 | D4: -0.003585315 | E4: 0.01123 | F4: 0.016515692
A5: 38107 | B5: -0.017804105 | C5: -0.046674279 | D5: -0.085476236 | E5: -0.028399998 | F5: -0.043864055
A6: 38138 | B6: -0.0021877217 | C6: 0.049558317 | D6: 0.043707136 | E6: -0.0069499962 | F6: 0.015257637
A7: 38168 | B7: 0.0088462613 | C7: 0.02767475 | D7: -0.003405782 | E7: -0.0011000051 | F7: -0.0014189512
A8: 38198 | B8: 0.0089616863 | C8: -0.075513604 | D8: 0.019774085 | E8: -0.0032899965 | F8: 0.014743519
A9: 38230 | B9: 0.015418905 | C9: -0.053303303 | D9: -0.02423192 | E9: -0.0023300047 | F9: 0.023573374
A10: 38260 | B10: 0.0015233914 | C10: 0.029183188 | D10: 0.12160577 | E10: 0.0083500021 | F10: 0.0022524055
A11: 38289 | B11: 0.0080551512 | C11: 0.052396363 | D11: -0.04206768 | E11: 0.0083800005 | F11: 0.014042126
A12: 38321 | B12: -0.0024905287 | C12: 0.048616196 | D12: 0.050911975 | E12: 0.028050002 | F12: -0.0045737489
A13: 38352 | B13: 0.0070429408 | C13: 0.028487641 | D13: 0.050918294 | E13: 0.0060599975 | F13: 0.012207878
... A121: 41639 | B121: -0.0047182963 | C121: 0.041327863 | D121: 0.048938505 | E121: 0.0047046249 | F121: -0.020848048

Sheet Factors
B1: US Muni | C1: US Tbill 1-3yr | D1: US AGG | E1: Global AGG | F1: US Dollar | G1: Commodities | H1: Long Short HF | I1: Event Driven HF | J1: HF FOF Div | K1: Relative Value HF | L1: EM Bond | M1: TIPs | N1: High Yield | O1: MSCI World | P1: MSCI Canada | Q1: MSCI EAFE | R1: MSCI EM Equity | S1: MSCI Europe | T1: MSCI Japan | U1: MSCI Asia ex-J | V1: US Growth | W1: US Value | X1: US Small Cap | Y1: US Mid Cap | Z1: Gold | AA1: S&P500 | AB1: Cash
B2: LM17TR | C2: LT01TRUU | D2: LBUSTRUU | E2: LEGATRUU | F2: USTW$ | G2: BCOMTR | H2: HFRIEHI | I2: HFRIEDI | J2: HFRIFOFD | K2: HFRIRVA | L2: JPEIGLBL | M2: SPBDU1ST | N2: H0A0 | O2: NDDUWI | P2: NDDUCA | Q2: NDDUEAFE | R2: NDUEEGF | S2: NDDUE15 | T2: NDDUJN | U2: NDUECAXJ | V2: RU10GRTR | W2: RU10VATR | X2: RU20INTR | Y2: RUMCINTR | Z2: GOLDS | AA2: SPTR | AB2: LD12TRUU
B3: Factor | C3: Factor | D3: Factor | E3: Factor | F3: Factor | G3: Factor | H3: Factor | I3: Factor | J3: Factor | K3: Factor | L3: Factor | M3: Factor | N3: Factor | O3: Factor | P3: Factor | Q3: Factor | R3: Factor | S3: Factor | T3: Factor | U3: Factor | V3: Factor | W3: Factor | X3: Factor | Y3: Factor | Z3: Factor | AA3: Factor | AB3: Factor | AD3: =COUNT(D4:D123) -> 120
A4: 38016 | B4: 0.0045136227 | C4: 0.0021072108 | D4: 0.0080453023 | E4: 0.0037328896 | F4: -0.020592772 | G4: 0.018131402 | H4: 0.019500002 | I4: 0.027989998 | J4: 0.01538002 | K4: 0.012109999 | L4: 0.0051267546 | M4: 0.012326082 | N4: 0.016153008 | O4: 0.016045881 | P4: 0.010467978 | Q4: 0.014140666 | R4: 0.034921371 | S4: 0.01169109 | T4: 0.018092314 | U4: 0.060155692 | V4: 0.020422332 | W4: 0.017583724 | X4: 0.043445899 | Y4: 0.029050476 | Z4: -0.031291371 | AA4: 0.018354972 | AB4: 0.00073130599 | AD4: {=SUMPRODUCT(--(Data!A2:A121<>Factors!A4:A123))} -> 0
A5: 38044 | B5: 0.014482164 | C5: 0.0050261565 | D5: 0.010824142 | E5: 0.0051522151 | F5: 0.0056063938 | G5: 0.06488201 | H5: 0.011099999 | I5: 0.012020003 | J5: 0.010909983 | K5: 0.0055000077 | L5: 0.0034824821 | M5: 0.024775375 | N5: -0.001096591 | O5: 0.016745271 | P5: 0.021644467 | Q5: 0.023084357 | R5: 0.045857115 | S5: 0.029289311 | T5: -0.0029369057 | U5: 0.033519226 | V5: 0.0063532895 | W5: 0.0214318 | X5: 0.0089643315 | Y5: 0.0215344 | Z5: -0.015654119 | AA5: 0.013899444 | AB5: 0.00073077157
A6: 38077 | B6: -0.0047764906 | C6: 0.0032149418 | D6: 0.0074889868 | E6: 0.011076524 | F6: 0.018216191 | G6: 0.030877435 | H6: 0.0035899977 | I6: 0.00057999971 | J6: 0.0044400219 | K6: 0.0043299894 | L6: 0.024958811 | M6: 0.017390173 | N6: 0.0066713818 | O6: -0.0066356142 | P6: -0.0049301964 | Q6: 0.0056267339 | R6: 0.012497891 | S6: -0.031163746 | T6: 0.1342725 | U6: -0.017081109 | V6: -0.01855019 | W6: -0.0087520788 | X6: 0.0093196653 | Y6: 0.00020896228 | Z6: 0.076486179 | AA6: -0.015086233 | AB6: 0.0007910911
A7: 38107 | B7: -0.020876864 | C7: -0.010071723 | D7: -0.026016616 | E7: -0.036564036 | F7: 0.011406884 | G7: -0.017736548 | H7: -0.020779997 | I7: -0.005619991 | J7: -0.0070900013 | K7: -0.0050599988 | L7: -0.054311023 | M7: -0.046496063 | N7: -0.0066013073 | O7: -0.020481468 | P7: -0.08338931 | Q7: -0.022620941 | R7: -0.08188064 | S7: -0.0082941921 | T7: -0.054216945 | U7: -0.054968837 | V7: -0.011625293 | W7: -0.024439606 | X7: -0.050984404 | Y7: -0.036717449 | Z7: -0.093094149 | AA7: -0.015698428 | AB7: 0.00079046577
A8: 38138 | B8: -0.0022641617 | C8: -0.0011304661 | D8: -0.0040058707 | E8: 0.0049003612 | F8: 0.016968154 | G8: 0.016954736 | H8: -0.0019099969 | I8: -0.0031200008 | J8: -0.008780017 | K8: -0.0034499938 | L8: -0.014827674 | M8: 0.016443736 | N8: -0.015711509 | O8: 0.0091110062 | P8: 0.026529007 | Q8: 0.0033625107 | R8: -0.019950299 | S8: 0.016240393 | T8: -0.035112696 | U8: -0.033586761 | V8: 0.018638848 | W8: 0.010198344 | X8: 0.015916286 | Y8: 0.024813011 | Z8: 0.022753717 | AA8: 0.013722899 | AB8: 0.00078984142
A9: 38168 | B9: 0.0033728521 | C9: -0.00010288595 | D9: 0.0056515785 | E9: 0.002922566 | F9: -0.015797072 | G9: -0.041462267 | H9: 0.010649995 | I9: 0.017579991 | J9: 0.0036000126 | K9: 0.0016100011 | L9: 0.014683749 | M9: -0.0026148152 | N9: 0.014527413 | O9: 0.020528812 | P9: 0.042358963 | Q9: 0.021910249 | R9: 0.0042593199 | S9: 0.013375713 | T9: 0.053855015 | U9: -0.0090281508 | V9: 0.012495751 | W9: 0.023628198 | X9: 0.042113399 | Y9: 0.027662371 | Z9: -0.003286563 | AA9: 0.019444937 | AB9: 0.0006677999
A10: 38198 | B10: 0.011548622 | C10: 0.0036528271 | D10: 0.009912255 | E10: -0.0002074828 | F10: -0.012661881 | G10: 0.017666821 | H10: -0.01882 | I10: -0.0093100039 | J10: -0.0056499986 | K10: 0.0065199865 | L10: 0.029702254 | M10: 0.016134553 | N10: 0.013476433 | O10: -0.032649904 | P10: 0.00078729651 | Q10: -0.032453533 | R10: -0.018305484 | S10: -0.027519388 | T10: -0.059280322 | U10: -0.020739513 | V10: -0.056532161 | W10: -0.014086673 | X10: -0.067333187 | Y10: -0.043723073 | Z10: -0.0081166772 | AA10: -0.033096938 | AB10: 0.00097069708
A11: 38230 | B11: 0.01810155 | C11: 0.0071252819 | D11: 0.019075174 | E11: 0.021887267 | F11: 0.002919278 | G11: -0.018225954 | H11: -0.0036700004 | I11: 0.0049100023 | J11: -9.0006463e-05 | K11: 0.0082500151 | L11: 0.041283114 | M11: 0.025976512 | N11: 0.018171957 | O11: 0.0043952194 | P11: 0.00018400079 | Q11: 0.0044161094 | R11: 0.041469494 | S11: 0.00060337248 | T11: 0.0072436226 | U11: 0.048217876 | V11: -0.0049383484 | W11: 0.01422138 | X11: -0.005139345 | Y11: 0.0043296667 | Z11: 0.048075694 | AA11: 0.0040449416 | AB11: 0.0010909752
A12: 38260 | B12: 0.0037546187 | C12: -0.0008143737 | D12: 0.0027134997 | E12: 0.01181709 | F12: -0.0052064615 | G12: 0.068466451 | H12: 0.019870006 | I12: 0.013649999 | J12: 0.0082399999 | K12: 0.003559986 | L12: 0.016634612 | M12: 0.0015744976 | N12: 0.013931553 | O12: 0.018917544 | P12: 0.075638449 | Q12: 0.026135669 | R12: 0.057694842 | S12: 0.040104962 | T12: -0.02345812 | U12: 0.038444515 | V12: 0.0095108983 | W12: 0.015501419 | X12: 0.046945559 | Y12: 0.032462293 | Z12: 0.020495303 | AA12: 0.010830591 | AB12: 0.0012108736
A13: 38289 | B13: 0.0067472552 | C13: 0.0031582701 | D13: 0.0083857442 | E13: 0.023953957 | F13: -0.022843063 | G13: 0.016922451 | H13: 0.0047499926 | I13: 0.014890002 | J13: 0.0077799954 | K13: 0.0031099991 | L13: 0.016096913 | M13: 0.014200355 | N13: 0.019280206 | O13: 0.024470422 | P13: 0.062899424 | Q13: 0.034099709 | R13: 0.023892911 | S13: 0.036095656 | T13: 0.026112689 | U13: 0.0065278837 | V13: 0.015596337 | W13: 0.016623798 | X13: 0.019683992 | Y13: 0.027577689 | Z13: 0.02462642 | AA13: 0.015277272 | AB13: 0.0012094092
A14: 38321 | B14: -0.0086422779 | C14: -0.0051287259 | D14: -0.0079764104 | E14: 0.026496979 | F14: -0.038898974 | G14: -0.011978445 | H14: 0.033700004 | I14: 0.040329999 | J14: 0.026389991 | K14: 0.010670007 | L14: 0.0069900376 | M14: -0.0070595322 | N14: 0.01040404 | O14: 0.052531245 | P14: 0.040706624 | Q14: 0.068313245 | R14: 0.092572783 | S14: 0.073360512 | T14: 0.048261417 | U14: 0.088702668 | V14: 0.034398424 | W14: 0.050557961 | X14: 0.08673848 | Y14: 0.060929688 | Z14: 0.05226928 | AA14: 0.040461567 | AB14: 0.0013891405
A15: 38352 | B15: 0.0097161351 | C15: 0.0021437321 | D15: 0.0092011222 | E15: 0.015321934 | F15: -0.010706752 | G15: -0.049106105 | H15: 0.017610003 | I15: 0.027990001 | J15: 0.01505 | K15: 0.0074600062 | L15: 0.025041357 | M15: 0.013768153 | N15: 0.015081436 | O15: 0.038173111 | P15: 0.018426114 | Q15: 0.043862591 | R15: 0.048028048 | S15: 0.042347221 | T15: 0.05128994 | U15: 0.030686401 | V15: 0.039208485 | W15: 0.033486511 | X15: 0.029599683 | Y15: 0.042566524 | Z15: -0.027719259 | AA15: 0.034028662 | AB15: 0.0019300362
A16: 38383 | B16: 0.0052499575 | C16: -0.00040745645 | D16: 0.0062794738 | E16: -0.010524264 | F16: 0.011685047 | G16: 0.010434131 | H16: -0.0058200013 | I16: -0.0014799961 | J16: 0.00017001186 | K16: 0.0030099913 | L16: 0.0062656245 | M16: 0.0054076539 | N16: -0.001018961 | O16: -0.022514369 | P16: -0.039803124 | Q16: -0.018347112 | R16: 0.0025397323 | S16: -0.018534402 | T16: -0.023222332 | U16: 0.0063491433 | V16: -0.033348503 | W16: -0.017750648 | X16: -0.041723392 | Y16: -0.024751523 | Z16: -0.036150074 | AA16: -0.02437501 | AB16: 0.0016855285
... A123: 41639 | B123: -0.0015690491 | C123: -0.0013934785 | D123: -0.0056511476 | E123: -0.005970907 | F123: 0.0021583472 | G123: 0.01239895 | H123: 0.014143492 | I123: 0.011934679 | J123: 0.015226749 | K123: 0.0076849904 | L123: 0.0058312774 | M123: -0.020891371 | N123: 0.0054797726 | O123: 0.02115966 | P123: 0.016119331 | Q123: 0.014962929 | R123: -0.014457785 | S123: 0.02238006 | T123: 0.0079577136 | U123: -0.010935544 | V123: 0.028564868 | W123: 0.025327426 | X123: 0.019680206 | Y123: 0.029770245 | Z123: -0.04125743 | AA123: 0.025316045 | AB123: 5.2050802e-05

Sheet Asset_Stats
B1: A1 | C1: A2 | D1: A3 | E1: A4 | F1: A5 | H1: Date | I1: Cumulative Return A1 | J1: Drawdown A1 | K1: Cumulative Return A2 | L1: Drawdown A2 | M1: Cumulative Return A3 | N1: Drawdown A3 | O1: Cumulative Return A4 | P1: Drawdown A4 | Q1: Cumulative Return A5 | R1: Drawdown A5
A2: Mean (Monthly) | B2: =AVERAGE(Data!B2:B121) -> 0.0037928377 | C2: =AVERAGE(Data!C2:C121) -> 0.0070011042 | D2: =AVERAGE(Data!D2:D121) -> 0.007773466 | E2: =AVERAGE(Data!E2:E121) -> 0.0035551713 | F2: =AVERAGE(Data!F2:F121) -> 0.004531784 | H2: =Data!A2 -> 38016 | I2: =1+Data!B2 -> 1.0062656 | J2: =I2/MAX($I$2:I2) - 1 -> 0 | K2: =1+Data!C2 -> 1.0347705 | L2: =K2/MAX($K$2:K2) - 1 -> 0 | M2: =1+Data!D2 -> 1.0326098 | N2: =M2/MAX($M$2:M2) - 1 -> 0 | O2: =1+Data!E2 -> 1.00646 | P2: =O2/MAX($O$2:O2) - 1 -> 0 | Q2: =1+Data!F2 -> 1.0118274 | R2: =Q2/MAX($Q$2:Q2) - 1 -> 0
A3: Mean (Annualized) | B3: =B2*12 -> 0.045514052 | C3: =C2*12 -> 0.08401325 | D3: =D2*12 -> 0.093281592 | E3: =E2*12 -> 0.042662055 | F3: =F2*12 -> 0.054381408 | H3: =Data!A3 -> 38044 | I3: =I2*(1+Data!B3) -> 1.0147467 | J3: =I3/MAX($I$2:I3) - 1 -> 0 | K3: =K2*(1+Data!C3) -> 1.0011127 | L3: =K3/MAX($K$2:K3) - 1 -> -0.032526882 | M3: =M2*(1+Data!D3) -> 1.1193133 | N3: =M3/MAX($M$2:M3) - 1 -> 0 | O3: =O2*(1+Data!E3) -> 1.0265791 | P3: =O3/MAX($O$2:O3) - 1 -> 0 | Q3: =Q2*(1+Data!F3) -> 1.0358668 | R3: =Q3/MAX($Q$2:Q3) - 1 -> 0
A4: Std Dev Monthly (sample) | B4: =_xlfn.STDEV.S(Data!B2:B121) -> 0.0076565012 | C4: =_xlfn.STDEV.S(Data!C2:C121) -> 0.053770802 | D4: =_xlfn.STDEV.S(Data!D2:D121) -> 0.072056103 | E4: =_xlfn.STDEV.S(Data!E2:E121) -> 0.014021218 | F4: =_xlfn.STDEV.S(Data!F2:F121) -> 0.020592099 | H4: =Data!A4 -> 38077 | I4: =I3*(1+Data!B4) -> 1.0191943 | J4: =I4/MAX($I$2:I4) - 1 -> 0 | K4: =K3*(1+Data!C4) -> 0.9744089 | L4: =K4/MAX($K$2:K4) - 1 -> -0.058333333 | M4: =M3*(1+Data!D4) -> 1.1153003 | N4: =M4/MAX($M$2:M4) - 1 -> -0.003585315 | O4: =O3*(1+Data!E4) -> 1.0381076 | P4: =O4/MAX($O$2:O4) - 1 -> 0 | Q4: =Q3*(1+Data!F4) -> 1.0529749 | R4: =Q4/MAX($Q$2:Q4) - 1 -> 0
A5: Std Dev Annualized | B5: =B4*SQRT(12) -> 0.026522898 | C5: =C4*SQRT(12) -> 0.18626752 | D5: =D4*SQRT(12) -> 0.24960966 | E5: =E4*SQRT(12) -> 0.048570925 | F5: =F4*SQRT(12) -> 0.071333122 | H5: =Data!A5 -> 38107 | I5: =I4*(1+Data!B5) -> 1.0010485 | J5: =I5/MAX($I$2:I5) - 1 -> -0.017804105 | K5: =K4*(1+Data!C5) -> 0.92892907 | L5: =K5/MAX($K$2:K5) - 1 -> -0.10228495 | M5: =M4*(1+Data!D5) -> 1.0199686 | N5: =M5/MAX($M$2:M5) - 1 -> -0.088755092 | O5: =O4*(1+Data!E5) -> 1.0086254 | P5: =O5/MAX($O$2:O5) - 1 -> -0.028399998 | Q5: =Q4*(1+Data!F5) -> 1.0067871 | R5: =Q5/MAX($Q$2:Q5) - 1 -> -0.043864055
A6: Worst Month | B6: =MIN(Data!B2:B121) -> -0.017804105 | C6: =MIN(Data!C2:C121) -> -0.17793994 | D6: =MIN(Data!D2:D121) -> -0.26884656 | E6: =MIN(Data!E2:E121) -> -0.028399998 | F6: =MIN(Data!F2:F121) -> -0.09429025 | H6: =Data!A6 -> 38138 | I6: =I5*(1+Data!B6) -> 0.99885849 | J6: =I6/MAX($I$2:I6) - 1 -> -0.019952876 | K6: =K5*(1+Data!C6) -> 0.97496523 | L6: =K6/MAX($K$2:K6) - 1 -> -0.057795699 | M6: =M5*(1+Data!D6) -> 1.0645485 | N6: =M6/MAX($M$2:M6) - 1 -> -0.048927187 | O6: =O5*(1+Data!E6) -> 1.0016154 | P6: =O6/MAX($O$2:O6) - 1 -> -0.035152615 | Q6: =Q5*(1+Data!F6) -> 1.0221483 | R6: =Q6/MAX($Q$2:Q6) - 1 -> -0.02927568
A7: Best Month | B7: =MAX(Data!B2:B121) -> 0.039284057 | C7: =MAX(Data!C2:C121) -> 0.12138805 | D7: =MAX(Data!D2:D121) -> 0.22182415 | E7: =MAX(Data!E2:E121) -> 0.042192468 | F7: =MAX(Data!F2:F121) -> 0.072092418 | H7: =Data!A7 -> 38168 | I7: =I6*(1+Data!B7) -> 1.0076946 | J7: =I7/MAX($I$2:I7) - 1 -> -0.011283123 | K7: =K6*(1+Data!C7) -> 1.0019471 | L7: =K7/MAX($K$2:K7) - 1 -> -0.03172043 | M7: =M6*(1+Data!D7) -> 1.0609229 | N7: =M7/MAX($M$2:M7) - 1 -> -0.052166334 | O7: =O6*(1+Data!E7) -> 1.0005136 | P7: =O7/MAX($O$2:O7) - 1 -> -0.036213952 | Q7: =Q6*(1+Data!F7) -> 1.0206979 | R7: =Q7/MAX($Q$2:Q7) - 1 -> -0.03065309
A8: Skewness | B8: =SKEW(Data!B2:B121) -> 0.46230495 | C8: =SKEW(Data!C2:C121) -> -0.53708439 | D8: =SKEW(Data!D2:D121) -> -0.3399279 | E8: =SKEW(Data!E2:E121) -> 0.24160526 | F8: =SKEW(Data!F2:F121) -> -0.91822856 | H8: =Data!A8 -> 38198 | I8: =I7*(1+Data!B8) -> 1.0167253 | J8: =I8/MAX($I$2:I8) - 1 -> -0.002422553 | K8: =K7*(1+Data!C8) -> 0.92628651 | L8: =K8/MAX($K$2:K8) - 1 -> -0.10483871 | M8: =M7*(1+Data!D8) -> 1.0819017 | N8: =M8/MAX($M$2:M8) - 1 -> -0.03342379 | O8: =O7*(1+Data!E8) -> 0.99722195 | P8: =O8/MAX($O$2:O8) - 1 -> -0.039384804 | Q8: =Q7*(1+Data!F8) -> 1.0357466 | R8: =Q8/MAX($Q$2:Q8) - 1 -> -0.016361506
A9: Excess kurtosis | B9: =KURT(Data!B2:B121) -> 3.3598901 | C9: =KURT(Data!C2:C121) -> 0.69459609 | D9: =KURT(Data!D2:D121) -> 1.4988551 | E9: =KURT(Data!E2:E121) -> -0.21081532 | F9: =KURT(Data!F2:F121) -> 5.3680402 | H9: =Data!A9 -> 38230 | I9: =I8*(1+Data!B9) -> 1.0324021 | J9: =I9/MAX($I$2:I9) - 1 -> 0 | K9: =K8*(1+Data!C9) -> 0.87691238 | L9: =K9/MAX($K$2:K9) - 1 -> -0.15255376 | M9: =M8*(1+Data!D9) -> 1.0556851 | N9: =M9/MAX($M$2:M9) - 1 -> -0.056845788 | O9: =O8*(1+Data!E9) -> 0.99489842 | P9: =O9/MAX($O$2:O9) - 1 -> -0.041623042 | Q9: =Q8*(1+Data!F9) -> 1.0601627 | R9: =Q9/MAX($Q$2:Q9) - 1 -> 0
A10: Jarque-Bera stat | B10: =120/6 * (B8^2 + B9^2/4) -> 60.718824 | C10: =120/6 * (C8^2 + C9^2/4) -> 8.1815115 | D10: =120/6 * (D8^2 + D9^2/4) -> 13.543853 | E10: =120/6 * (E8^2 + E9^2/4) -> 1.3896775 | F10: =120/6 * (F8^2 + F9^2/4) -> 160.94215 | G10: (n / 6) * (S^2 + K^2 / 4) | H10: =Data!A10 -> 38260 | I10: =I9*(1+Data!B10) -> 1.0339748 | J10: =I10/MAX($I$2:I10) - 1 -> 0 | K10: =K9*(1+Data!C10) -> 0.90250348 | L10: =K10/MAX($K$2:K10) - 1 -> -0.12782258 | M10: =M9*(1+Data!D10) -> 1.1840625 | N10: =M10/MAX($M$2:M10) - 1 -> 0 | O10: =O9*(1+Data!E10) -> 1.0032058 | P10: =O10/MAX($O$2:O10) - 1 -> -0.033620593 | Q10: =Q9*(1+Data!F10) -> 1.0625506 | R10: =Q10/MAX($Q$2:Q10) - 1 -> 0
A11: JB p-value | B11: =_xlfn.CHISQ.DIST.RT(B10, 2) -> 6.5324331e-14 | C11: =_xlfn.CHISQ.DIST.RT(C10, 2) -> 0.016726587 | D11: =_xlfn.CHISQ.DIST.RT(D10, 2) -> 0.0011454859 | E11: =_xlfn.CHISQ.DIST.RT(E10, 2) -> 0.49915493 | F11: =_xlfn.CHISQ.DIST.RT(F10, 2) -> 1.1268223e-35 | H11: =Data!A11 -> 38289 | I11: =I10*(1+Data!B11) -> 1.0423037 | J11: =I11/MAX($I$2:I11) - 1 -> 0 | K11: =K10*(1+Data!C11) -> 0.94979138 | L11: =K11/MAX($K$2:K11) - 1 -> -0.082123656 | M11: =M10*(1+Data!D11) -> 1.1342517 | N11: =M11/MAX($M$2:M11) - 1 -> -0.04206768 | O11: =O10*(1+Data!E11) -> 1.0116127 | P11: =O11/MAX($O$2:O11) - 1 -> -0.025522333 | Q11: =Q10*(1+Data!F11) -> 1.0774711 | R11: =Q11/MAX($Q$2:Q11) - 1 -> 0
A12: Normality | B12: =IF(B11<0.05, "REJECT", "PASS") -> REJECT | C12: =IF(C11<0.05, "REJECT", "PASS") -> REJECT | D12: =IF(D11<0.05, "REJECT", "PASS") -> REJECT | E12: =IF(E11<0.05, "REJECT", "PASS") -> PASS | F12: =IF(F11<0.05, "REJECT", "PASS") -> REJECT | H12: =Data!A12 -> 38321 | I12: =I11*(1+Data!B12) -> 1.0397078 | J12: =I12/MAX($I$2:I12) - 1 -> -0.0024905287 | K12: =K11*(1+Data!C12) -> 0.99596662 | L12: =K12/MAX($K$2:K12) - 1 -> -0.0375 | M12: =M11*(1+Data!D12) -> 1.1919987 | N12: =M12/MAX($M$2:M12) - 1 -> 0 | O12: =O11*(1+Data!E12) -> 1.0399884 | P12: =O12/MAX($O$2:O12) - 1 -> 0 | Q12: =Q11*(1+Data!F12) -> 1.072543 | R12: =Q12/MAX($Q$2:Q12) - 1 -> -0.0045737489
A13: 95% historical VaR | B13: =_xlfn.PERCENTILE.INC(Data!B2:B121, 0.05) -> -0.0070430627 | C13: =_xlfn.PERCENTILE.INC(Data!C2:C121, 0.05) -> -0.081664641 | D13: =_xlfn.PERCENTILE.INC(Data!D2:D121, 0.05) -> -0.096636539 | E13: =_xlfn.PERCENTILE.INC(Data!E2:E121, 0.05) -> -0.017456733 | F13: =_xlfn.PERCENTILE.INC(Data!F2:F121, 0.05) -> -0.029011251 | H13: =Data!A13 -> 38352 | I13: =I12*(1+Data!B13) -> 1.0470304 | J13: =I13/MAX($I$2:I13) - 1 -> 0 | K13: =K12*(1+Data!C13) -> 1.0243394 | L13: =K13/MAX($K$2:K13) - 1 -> -0.010080645 | M13: =M12*(1+Data!D13) -> 1.2526933 | N13: =M13/MAX($M$2:M13) - 1 -> 0 | O13: =O12*(1+Data!E13) -> 1.0462907 | P13: =O13/MAX($O$2:O13) - 1 -> 0 | Q13: =Q12*(1+Data!F13) -> 1.0856364 | R13: =Q13/MAX($Q$2:Q13) - 1 -> 0
A14: 99% historical VaR | B14: =_xlfn.PERCENTILE.INC(Data!B2:B121, 0.01) -> -0.015093948 | C14: =_xlfn.PERCENTILE.INC(Data!C2:C121, 0.01) -> -0.12683051 | D14: =_xlfn.PERCENTILE.INC(Data!D2:D121, 0.01) -> -0.18773159 | E14: =_xlfn.PERCENTILE.INC(Data!E2:E121, 0.01) -> -0.025625164 | F14: =_xlfn.PERCENTILE.INC(Data!F2:F121, 0.01) -> -0.052599643 | H14: =Data!A14 -> 38383 | I14: =I13*(1+Data!B14) -> 1.0526027 | J14: =I14/MAX($I$2:I14) - 1 -> 0 | K14: =K13*(1+Data!C14) -> 0.97065369 | L14: =K14/MAX($K$2:K14) - 1 -> -0.061962366 | M14: =M13*(1+Data!D14) -> 1.2198205 | N14: =M14/MAX($M$2:M14) - 1 -> -0.02624166 | O14: =O13*(1+Data!E14) -> 1.0402641 | P14: =O14/MAX($O$2:O14) - 1 -> -0.005760002 | Q14: =Q13*(1+Data!F14) -> 1.0881686 | R14: =Q14/MAX($Q$2:Q14) - 1 -> 0
A15: 95% historical CVaR | B15: =AVERAGEIF(Data!B2:B121, "<="&B13) -> -0.012979702 | C15: =AVERAGEIF(Data!C2:C121, "<="&C13) -> -0.11998939 | D15: =AVERAGEIF(Data!D2:D121, "<="&D13) -> -0.15337411 | E15: =AVERAGEIF(Data!E2:E121, "<="&E13) -> -0.022777601 | F15: =AVERAGEIF(Data!F2:F121, "<="&F13) -> -0.0526241 | H15: =Data!A15 -> 38411 | I15: =I14*(1+Data!B15) -> 1.0477237 | J15: =I15/MAX($I$2:I15) - 1 -> -0.0046350966 | K15: =K14*(1+Data!C15) -> 0.97107093 | L15: =K15/MAX($K$2:K15) - 1 -> -0.06155914 | M15: =M14*(1+Data!D15) -> 1.2925751 | N15: =M15/MAX($M$2:M15) - 1 -> 0 | O15: =O14*(1+Data!E15) -> 1.0590513 | P15: =O15/MAX($O$2:O15) - 1 -> 0 | Q15: =Q14*(1+Data!F15) -> 1.0818062 | R15: =Q15/MAX($Q$2:Q15) - 1 -> -0.0058469197
A16: 99% historical CVaR | B16: =AVERAGEIF(Data!B2:B121, "<="&B14) -> -0.016568381 | C16: =AVERAGEIF(Data!C2:C121, "<="&C14) -> -0.1525952 | D16: =AVERAGEIF(Data!D2:D121, "<="&D14) -> -0.2347165 | E16: =AVERAGEIF(Data!E2:E121, "<="&E14) -> -0.027318726 | F16: =AVERAGEIF(Data!F2:F121, "<="&F14) -> -0.074086158 | H16: =Data!A16 -> 38442 | I16: =I15*(1+Data!B16) -> 1.0457789 | J16: =I16/MAX($I$2:I16) - 1 -> -0.0064827088 | K16: =K15*(1+Data!C16) -> 0.9488178 | L16: =K16/MAX($K$2:K16) - 1 -> -0.083064516 | M16: =M15*(1+Data!D16) -> 1.30815 | N16: =M16/MAX($M$2:M16) - 1 -> 0 | O16: =O15*(1+Data!E16) -> 1.0526864 | P16: =O16/MAX($O$2:O16) - 1 -> -0.0060100031 | Q16: =Q15*(1+Data!F16) -> 1.0786971 | R16: =Q16/MAX($Q$2:Q16) - 1 -> -0.0087041046
A17: Sharpe (monthly) | B17: =(B2 - AVERAGE(Factors!AB4:AB123)) / B4 -> 0.32340152 | C17: =(C2 - AVERAGE(Factors!AB4:AB123)) / C4 -> 0.10571519 | D17: =(D2 - AVERAGE(Factors!AB4:AB123)) / D4 -> 0.089607294 | E17: =(E2 - AVERAGE(Factors!AB4:AB123)) / E4 -> 0.15964787 | F17: =(F2 - AVERAGE(Factors!AB4:AB123)) / F4 -> 0.15613126 | H17: =Data!A17 -> 38471 | I17: =I16*(1+Data!B17) -> 1.0573547 | J17: =I17/MAX($I$2:I17) - 1 -> 0 | K17: =K16*(1+Data!C17) -> 0.91126565 | L17: =K17/MAX($K$2:K17) - 1 -> -0.11935484 | M17: =M16*(1+Data!D17) -> 1.2503684 | N17: =M17/MAX($M$2:M17) - 1 -> -0.044170462 | O17: =O16*(1+Data!E17) -> 1.0415174 | P17: =O17/MAX($O$2:O17) - 1 -> -0.016556239 | Q17: =Q16*(1+Data!F17) -> 1.1021515 | R17: =Q17/MAX($Q$2:Q17) - 1 -> 0
A18: Sharpe (annualized) | B18: =B17 *SQRT(12) -> 1.1202957 | C18: =C17 *SQRT(12) -> 0.36620817 | D18: =D17 *SQRT(12) -> 0.31040877 | E18: =E17 *SQRT(12) -> 0.55303645 | F18: =F17 *SQRT(12) -> 0.54085456 | H18: =Data!A18 -> 38503 | I18: =I17*(1+Data!B18) -> 1.0656836 | J18: =I18/MAX($I$2:I18) - 1 -> 0 | K18: =K17*(1+Data!C18) -> 0.9821975 | L18: =K18/MAX($K$2:K18) - 1 -> -0.050806452 | M18: =M17*(1+Data!D18) -> 1.2357414 | N18: =M18/MAX($M$2:M18) - 1 -> -0.05535192 | O18: =O17*(1+Data!E18) -> 1.0451106 | P18: =O18/MAX($O$2:O18) - 1 -> -0.013163355 | Q18: =Q17*(1+Data!F18) -> 1.1084098 | R18: =Q18/MAX($Q$2:Q18) - 1 -> 0
A19: Max Drawdown | B19: =MIN(J2:J121) -> -0.028466629 | C19: =MIN(L2:L121) -> -0.50806048 | D19: =MIN(N2:N121) -> -0.62329575 | E19: =MIN(P2:P121) -> -0.080200886 | F19: =MIN(R2:R121) -> -0.13545668 | H19: =Data!A19 -> 38533 | I19: =I18*(1+Data!B19) -> 1.0695478 | J19: =I19/MAX($I$2:I19) - 1 -> 0 | K19: =K18*(1+Data!C19) -> 0.9650904 | L19: =K19/MAX($K$2:K19) - 1 -> -0.06733871 | M19: =M18*(1+Data!D19) -> 1.2306282 | N19: =M19/MAX($M$2:M19) - 1 -> -0.05926067 | O19: =O18*(1+Data!E19) -> 1.0561365 | P19: =O19/MAX($O$2:O19) - 1 -> -0.0027522269 | Q19: =Q18*(1+Data!F19) -> 1.1118635 | R19: =Q19/MAX($Q$2:Q19) - 1 -> 0
H20: =Data!A20 -> 38562 | I20: =I19*(1+Data!B20) -> 1.0641869 | J20: =I20/MAX($I$2:I20) - 1 -> -0.0050122936 | K20: =K19*(1+Data!C20) -> 1.0215577 | L20: =K20/MAX($K$2:K20) - 1 -> -0.012768817 | M20: =M19*(1+Data!D20) -> 1.3075273 | N20: =M20/MAX($M$2:M20) - 1 -> -0.0004760318 | O20: =O19*(1+Data!E20) -> 1.0639625 | P20: =O20/MAX($O$2:O20) - 1 -> 0 | Q20: =Q19*(1+Data!F20) -> 1.0930085 | R20: =Q20/MAX($Q$2:Q20) - 1 -> -0.016957947
A21: Correlation Matrix | B21: Asset 1 | C21: Asset 2 | D21: Asset3 | E21: Asset 4 | F21: Asset 5 | H21: =Data!A21 -> 38595 | I21: =I20*(1+Data!B21) -> 1.073615 | J21: =I21/MAX($I$2:I21) - 1 -> 0 | K21: =K20*(1+Data!C21) -> 1.0191933 | L21: =K21/MAX($K$2:K21) - 1 -> -0.015053763 | M21: =M20*(1+Data!D21) -> 1.3358611 | N21: =M21/MAX($M$2:M21) - 1 -> 0 | O21: =O20*(1+Data!E21) -> 1.0716762 | P21: =O21/MAX($O$2:O21) - 1 -> 0 | Q21: =Q20*(1+Data!F21) -> 1.1177211 | R21: =Q21/MAX($Q$2:Q21) - 1 -> 0
A22: Asset 1 | B22: 1 | H22: =Data!A22 -> 38625 | I22: =I21*(1+Data!B22) -> 1.0679666 | J22: =I22/MAX($I$2:I22) - 1 -> -0.0052610853 | K22: =K21*(1+Data!C22) -> 1.022114 | L22: =K22/MAX($K$2:K22) - 1 -> -0.012231183 | M22: =M21*(1+Data!D22) -> 1.3601749 | N22: =M22/MAX($M$2:M22) - 1 -> 0 | O22: =O21*(1+Data!E22) -> 1.0942672 | P22: =O22/MAX($O$2:O22) - 1 -> 0 | Q22: =Q21*(1+Data!F22) -> 1.1139549 | R22: =Q22/MAX($Q$2:Q22) - 1 -> -0.0033695138
A23: Asset 2 | B23: -0.14089657 | C23: 1 | H23: =Data!A23 -> 38656 | I23: =I22*(1+Data!B23) -> 1.0605256 | J23: =I23/MAX($I$2:I23) - 1 -> -0.012191856 | K23: =K22*(1+Data!C23) -> 0.99972184 | L23: =K23/MAX($K$2:K23) - 1 -> -0.033870968 | M23: =M22*(1+Data!D23) -> 1.425104 | N23: =M23/MAX($M$2:M23) - 1 -> 0 | O23: =O22*(1+Data!E23) -> 1.0873295 | P23: =O23/MAX($O$2:O23) - 1 -> -0.0063400049 | Q23: =Q22*(1+Data!F23) -> 1.1005729 | R23: =Q23/MAX($Q$2:Q23) - 1 -> -0.015342041
A24: Asset3 | B24: -0.07002401 | C24: 0.48638569 | D24: 1 | H24: =Data!A24 -> 38686 | I24: =I23*(1+Data!B24) -> 1.0639755 | J24: =I24/MAX($I$2:I24) - 1 -> -0.0089784989 | K24: =K23*(1+Data!C24) -> 1.0636996 | L24: =K24/MAX($K$2:K24) - 1 -> 0 | M24: =M23*(1+Data!D24) -> 1.5575636 | N24: =M24/MAX($M$2:M24) - 1 -> 0 | O24: =O23*(1+Data!E24) -> 1.1032263 | P24: =O24/MAX($O$2:O24) - 1 -> 0 | Q24: =Q23*(1+Data!F24) -> 1.1021836 | R24: =Q24/MAX($Q$2:Q24) - 1 -> -0.013901037
A25: Asset 4 | B25: 0.032551131 | C25: 0.22608792 | D25: 0.3819485 | E25: 1 | H25: =Data!A25 -> 38716 | I25: =I24*(1+Data!B25) -> 1.0743844 | J25: =I25/MAX($I$2:I25) - 1 -> 0 | K25: =K24*(1+Data!C25) -> 1.0325452 | L25: =K25/MAX($K$2:K25) - 1 -> -0.029288703 | M25: =M24*(1+Data!D25) -> 1.6719713 | N25: =M25/MAX($M$2:M25) - 1 -> 0 | O25: =O24*(1+Data!E25) -> 1.1172924 | P25: =O25/MAX($O$2:O25) - 1 -> 0 | Q25: =Q24*(1+Data!F25) -> 1.1107256 | R25: =Q25/MAX($Q$2:Q25) - 1 -> -0.0062586926
A26: Asset 5 | B26: 0.66610041 | C26: 0.12518698 | D26: 0.22467058 | E26: 0.1519541 | F26: 1 | H26: =Data!A26 -> 38748 | I26: =I25*(1+Data!B26) -> 1.0778428 | J26: =I26/MAX($I$2:I26) - 1 -> 0 | K26: =K25*(1+Data!C26) -> 1.0656467 | L26: =K26/MAX($K$2:K26) - 1 -> 0 | M26: =M25*(1+Data!D26) -> 1.867568 | N26: =M26/MAX($M$2:M26) - 1 -> 0 | O26: =O25*(1+Data!E26) -> 1.1441186 | P26: =O26/MAX($O$2:O26) - 1 -> 0 | Q26: =Q25*(1+Data!F26) -> 1.1118715 | R26: =Q26/MAX($Q$2:Q26) - 1 -> -0.0052335001
H27: =Data!A27 -> 38776 | I27: =I26*(1+Data!B27) -> 1.0828655 | J27: =I27/MAX($I$2:I27) - 1 -> 0 | K27: =K26*(1+Data!C27) -> 1.055911 | L27: =K27/MAX($K$2:K27) - 1 -> -0.0091359958 | M27: =M26*(1+Data!D27) -> 1.834287 | N27: =M27/MAX($M$2:M27) - 1 -> -0.017820491 | O27: =O26*(1+Data!E27) -> 1.1387184 | P27: =O27/MAX($O$2:O27) - 1 -> -0.0047199914 | Q27: =Q26*(1+Data!F27) -> 1.1086342 | R27: =Q27/MAX($Q$2:Q27) - 1 -> -0.0081298482
H28: =Data!A28 -> 38807 | I28: =I27*(1+Data!B28) -> 1.0736826 | J28: =I28/MAX($I$2:I28) - 1 -> -0.0084801349 | K28: =K27*(1+Data!C28) -> 1.0751043 | L28: =K28/MAX($K$2:K28) - 1 -> 0 | M28: =M27*(1+Data!D28) -> 1.9737627 | N28: =M28/MAX($M$2:M28) - 1 -> 0 | O28: =O27*(1+Data!E28) -> 1.1517795 | P28: =O28/MAX($O$2:O28) - 1 -> 0 | Q28: =Q27*(1+Data!F28) -> 1.0900677 | R28: =Q28/MAX($Q$2:Q28) - 1 -> -0.024740834
H29: =Data!A29 -> 38835 | I29: =I28*(1+Data!B29) -> 1.0737418 | J29: =I29/MAX($I$2:I29) - 1 -> -0.0084254748 | K29: =K28*(1+Data!C29) -> 1.0628651 | L29: =K29/MAX($K$2:K29) - 1 -> -0.011384217 | M29: =M28*(1+Data!D29) -> 2.4115909 | N29: =M29/MAX($M$2:M29) - 1 -> 0 | O29: =O28*(1+Data!E29) -> 1.1836146 | P29: =O29/MAX($O$2:O29) - 1 -> 0 | Q29: =Q28*(1+Data!F29) -> 1.0928563 | R29: =Q29/MAX($Q$2:Q29) - 1 -> -0.02224596
H30: =Data!A30 -> 38868 | I30: =I29*(1+Data!B30) -> 1.071704 | J30: =I30/MAX($I$2:I30) - 1 -> -0.010307346 | K30: =K29*(1+Data!C30) -> 0.98748261 | L30: =K30/MAX($K$2:K30) - 1 -> -0.081500647 | M30: =M29*(1+Data!D30) -> 2.6245477 | N30: =M30/MAX($M$2:M30) - 1 -> 0 | O30: =O29*(1+Data!E30) -> 1.1674701 | P30: =O30/MAX($O$2:O30) - 1 -> -0.013640001 | Q30: =Q29*(1+Data!F30) -> 1.0953163 | R30: =Q30/MAX($Q$2:Q30) - 1 -> -0.020045022
H31: =Data!A31 -> 38898 | I31: =I30*(1+Data!B31) -> 1.0737756 | J31: =I31/MAX($I$2:I31) - 1 -> -0.0083942404 | K31: =K30*(1+Data!C31) -> 0.97121001 | L31: =K31/MAX($K$2:K31) - 1 -> -0.096636481 | M31: =M30*(1+Data!D31) -> 2.4886353 | N31: =M31/MAX($M$2:M31) - 1 -> -0.051785046 | O31: =O30*(1+Data!E31) -> 1.1618196 | P31: =O31/MAX($O$2:O31) - 1 -> -0.018413978 | Q31: =Q30*(1+Data!F31) -> 1.0998197 | R31: =Q31/MAX($Q$2:Q31) - 1 -> -0.016015944
H32: =Data!A32 -> 38929 | I32: =I31*(1+Data!B32) -> 1.0891565 | J32: =I32/MAX($I$2:I32) - 1 -> 0 | K32: =K31*(1+Data!C32) -> 0.93449235 | L32: =K32/MAX($K$2:K32) - 1 -> -0.13078913 | M32: =M31*(1+Data!D32) -> 2.6483494 | N32: =M32/MAX($M$2:M32) - 1 -> 0 | O32: =O31*(1+Data!E32) -> 1.1587989 | P32: =O32/MAX($O$2:O32) - 1 -> -0.020966101 | Q32: =Q31*(1+Data!F32) -> 1.1159902 | R32: =Q32/MAX($Q$2:Q32) - 1 -> -0.0015485425
H33: =Data!A33 -> 38960 | I33: =I32*(1+Data!B33) -> 1.1049855 | J33: =I33/MAX($I$2:I33) - 1 -> 0 | K33: =K32*(1+Data!C33) -> 1.0127955 | L33: =K33/MAX($K$2:K33) - 1 -> -0.057956016 | M33: =M32*(1+Data!D33) -> 2.6873871 | N33: =M33/MAX($M$2:M33) - 1 -> 0 | O33: =O32*(1+Data!E33) -> 1.1614873 | P33: =O33/MAX($O$2:O33) - 1 -> -0.018694746 | Q33: =Q32*(1+Data!F33) -> 1.1340038 | R33: =Q33/MAX($Q$2:Q33) - 1 -> 0
H34: =Data!A34 -> 38989 | I34: =I33*(1+Data!B34) -> 1.1127139 | J34: =I34/MAX($I$2:I34) - 1 -> 0 | K34: =K33*(1+Data!C34) -> 1.0534075 | L34: =K34/MAX($K$2:K34) - 1 -> -0.020181113 | M34: =M33*(1+Data!D34) -> 2.720246 | N34: =M34/MAX($M$2:M34) - 1 -> 0 | O34: =O33*(1+Data!E34) -> 1.15266 | P34: =O34/MAX($O$2:O34) - 1 -> -0.026152669 | Q34: =Q33*(1+Data!F34) -> 1.1375696 | R34: =Q34/MAX($Q$2:Q34) - 1 -> 0
H35: =Data!A35 -> 39021 | I35: =I34*(1+Data!B35) -> 1.1207806 | J35: =I35/MAX($I$2:I35) - 1 -> 0 | K35: =K34*(1+Data!C35) -> 1.0968011 | L35: =K35/MAX($K$2:K35) - 1 -> 0 | M35: =M34*(1+Data!D35) -> 2.9369737 | N35: =M35/MAX($M$2:M35) - 1 -> 0 | O35: =O34*(1+Data!E35) -> 1.1657657 | P35: =O35/MAX($O$2:O35) - 1 -> -0.01508002 | Q35: =Q34*(1+Data!F35) -> 1.1350695 | R35: =Q35/MAX($Q$2:Q35) - 1 -> -0.0021977558
H36: =Data!A36 -> 39051 | I36: =I35*(1+Data!B36) -> 1.1336332 | J36: =I36/MAX($I$2:I36) - 1 -> 0 | K36: =K35*(1+Data!C36) -> 1.1324061 | L36: =K36/MAX($K$2:K36) - 1 -> 0 | M36: =M35*(1+Data!D36) -> 2.957143 | N36: =M36/MAX($M$2:M36) - 1 -> 0 | O36: =O35*(1+Data!E36) -> 1.1932428 | P36: =O36/MAX($O$2:O36) - 1 -> 0 | Q36: =Q35*(1+Data!F36) -> 1.1478585 | R36: =Q36/MAX($Q$2:Q36) - 1 -> 0
H37: =Data!A37 -> 39080 | I37: =I36*(1+Data!B37) -> 1.1305131 | J37: =I37/MAX($I$2:I37) - 1 -> -0.0027523346 | K37: =K36*(1+Data!C37) -> 1.1172462 | L37: =K37/MAX($K$2:K37) - 1 -> -0.013387374 | M37: =M36*(1+Data!D37) -> 2.8816069 | N37: =M37/MAX($M$2:M37) - 1 -> -0.025543594 | O37: =O36*(1+Data!E37) -> 1.208397 | P37: =O37/MAX($O$2:O37) - 1 -> 0 | Q37: =Q36*(1+Data!F37) -> 1.1218558 | R37: =Q37/MAX($Q$2:Q37) - 1 -> -0.022653179
H38: =Data!A38 -> 39113 | I38: =I37*(1+Data!B38) -> 1.1312403 | J38: =I38/MAX($I$2:I38) - 1 -> -0.0021108691 | K38: =K37*(1+Data!C38) -> 1.1349096 | L38: =K38/MAX($K$2:K38) - 1 -> 0 | M38: =M37*(1+Data!D38) -> 2.7607022 | N38: =M38/MAX($M$2:M38) - 1 -> -0.066429255 | O38: =O37*(1+Data!E38) -> 1.2128898 | P38: =O38/MAX($O$2:O38) - 1 -> 0 | Q38: =Q37*(1+Data!F38) -> 1.1248207 | R38: =Q38/MAX($Q$2:Q38) - 1 -> -0.020070228
... H121: =Data!A121 -> 41639 | I121: =I120*(1+Data!B121) -> 1.569607 | J121: =I121/MAX($I$2:I121) - 1 -> -0.018900235 | K121: =K120*(1+Data!C121) -> 1.9414465 | L121: =K121/MAX($K$2:K121) - 1 -> 0 | M121: =M120*(1+Data!D121) -> 1.8522172 | N121: =M121/MAX($M$2:M121) - 1 -> -0.44909233 | O121: =O120*(1+Data!E121) -> 1.5132686 | P121: =O121/MAX($O$2:O121) - 1 -> -0.063327799 | Q121: =Q120*(1+Data!F121) -> 1.6773749 | R121: =Q121/MAX($Q$2:Q121) - 1 -> -0.10802415

Sheet Histograms
A1: A1 Histogram
A2: Bin Upper | B2: Frequency | C2: Normal PDF
A3: -0.025 | B3: {=FREQUENCY(Data!B2:B121, A3:A14)} -> 0 | C3: =_xlfn.NORM.DIST(A3-0.0025, Asset_Stats!$B$2, Asset_Stats!$B$4, FALSE) * 0.005 * 120 -> 0.0073744686
A4: =A3+0.005 -> -0.02 | B4: 0 | C4: =_xlfn.NORM.DIST(A4-0.0025, Asset_Stats!$B$2, Asset_Stats!$B$4, FALSE) * 0.005 * 120 -> 0.08595537
A5: =A4+0.005 -> -0.015 | B5: 2 | C5: =_xlfn.NORM.DIST(A5-0.0025, Asset_Stats!$B$2, Asset_Stats!$B$4, FALSE) * 0.005 * 120 -> 0.65404201
A6: =A5+0.005 -> -0.01 | B6: 2 | C6: =_xlfn.NORM.DIST(A6-0.0025, Asset_Stats!$B$2, Asset_Stats!$B$4, FALSE) * 0.005 * 120 -> 3.2488423
A7: =A6+0.005 -> -0.005 | B7: 10 | C7: =_xlfn.NORM.DIST(A7-0.0025, Asset_Stats!$B$2, Asset_Stats!$B$4, FALSE) * 0.005 * 120 -> 10.53518
A8: =A7+0.005 -> 0 | B8: 17 | C8: =_xlfn.NORM.DIST(A8-0.0025, Asset_Stats!$B$2, Asset_Stats!$B$4, FALSE) * 0.005 * 120 -> 22.302094
A9: =A8+0.005 -> 0.005 | B9: 37 | C9: =_xlfn.NORM.DIST(A9-0.0025, Asset_Stats!$B$2, Asset_Stats!$B$4, FALSE) * 0.005 * 120 -> 30.820499
A10: =A9+0.005 -> 0.01 | B10: 30 | C10: =_xlfn.NORM.DIST(A10-0.0025, Asset_Stats!$B$2, Asset_Stats!$B$4, FALSE) * 0.005 * 120 -> 27.805073
A11: =A10+0.005 -> 0.015 | B11: 17 | C11: =_xlfn.NORM.DIST(A11-0.0025, Asset_Stats!$B$2, Asset_Stats!$B$4, FALSE) * 0.005 * 120 -> 16.375658
A12: =A11+0.005 -> 0.02 | B12: 4 | C12: =_xlfn.NORM.DIST(A12-0.0025, Asset_Stats!$B$2, Asset_Stats!$B$4, FALSE) * 0.005 * 120 -> 6.2959874
A13: =A12+0.005 -> 0.025 | B13: 0 | C13: =_xlfn.NORM.DIST(A13-0.0025, Asset_Stats!$B$2, Asset_Stats!$B$4, FALSE) * 0.005 * 120 -> 1.5802263
A14: =A13+0.005 -> 0.03 | B14: 0 | C14: =_xlfn.NORM.DIST(A14-0.0025, Asset_Stats!$B$2, Asset_Stats!$B$4, FALSE) * 0.005 * 120 -> 0.25891967
B15: 1
A16: A2 Histogram
A17: Bin Upper | B17: Frequency | C17: Normal PDF
A18: -0.22 | B18: {=FREQUENCY(Data!C4:C121, A18:A27)} -> 0 | C18: =_xlfn.NORM.DIST(A18-0.0025, Asset_Stats!$C$2, Asset_Stats!$C$4, FALSE) * 0.04 * 120 -> 0.0039430875
A19: =A18+0.04 -> -0.18 | B19: 0 | C19: =_xlfn.NORM.DIST(A19-0.0025, Asset_Stats!$C$2, Asset_Stats!$C$4, FALSE) * 0.04 * 120 -> 0.071545275
A20: =A19+0.04 -> -0.14 | B20: 1 | C20: =_xlfn.NORM.DIST(A20-0.0025, Asset_Stats!$C$2, Asset_Stats!$C$4, FALSE) * 0.04 * 120 -> 0.74643788
A21: =A20+0.04 -> -0.1 | B21: 3 | C21: =_xlfn.NORM.DIST(A21-0.0025, Asset_Stats!$C$2, Asset_Stats!$C$4, FALSE) * 0.04 * 120 -> 4.4779019
A22: =A21+0.04 -> -0.06 | B22: 11 | C22: =_xlfn.NORM.DIST(A22-0.0025, Asset_Stats!$C$2, Asset_Stats!$C$4, FALSE) * 0.04 * 120 -> 15.446271
A23: =A22+0.04 -> -0.02 | B23: 17 | C23: =_xlfn.NORM.DIST(A23-0.0025, Asset_Stats!$C$2, Asset_Stats!$C$4, FALSE) * 0.04 * 120 -> 30.636624
A24: =A23+0.04 -> 0.02 | B24: 34 | C24: =_xlfn.NORM.DIST(A24-0.0025, Asset_Stats!$C$2, Asset_Stats!$C$4, FALSE) * 0.04 * 120 -> 34.940278
A25: =A24+0.04 -> 0.06 | B25: 37 | C25: =_xlfn.NORM.DIST(A25-0.0025, Asset_Stats!$C$2, Asset_Stats!$C$4, FALSE) * 0.04 * 120 -> 22.912896
A26: =A25+0.04 -> 0.1 | B26: 11 | C26: =_xlfn.NORM.DIST(A26-0.0025, Asset_Stats!$C$2, Asset_Stats!$C$4, FALSE) * 0.04 * 120 -> 8.639762
A27: =A26+0.04 -> 0.14 | B27: 4 | C27: =_xlfn.NORM.DIST(A27-0.0025, Asset_Stats!$C$2, Asset_Stats!$C$4, FALSE) * 0.04 * 120 -> 1.8732328
B28: 0
A29: A3 Histogram
A30: Bin Upper | B30: Frequency | C30: Normal PDF
A31: -0.3 | B31: {=FREQUENCY(Data!D4:D121, A31:A40)} -> 0 | C31: =_xlfn.NORM.DIST(A31-0.0025, Asset_Stats!$D$2, Asset_Stats!$D$4, FALSE) * 0.06 * 120 -> 0.0037524045
A32: =A31+0.06 -> -0.24 | B32: 1 | C32: =_xlfn.NORM.DIST(A32-0.0025, Asset_Stats!$D$2, Asset_Stats!$D$4, FALSE) * 0.06 * 120 -> 0.095703343
A33: =A32+0.06 -> -0.18 | B33: 1 | C33: =_xlfn.NORM.DIST(A33-0.0025, Asset_Stats!$D$2, Asset_Stats!$D$4, FALSE) * 0.06 * 120 -> 1.2201708
A34: =A33+0.06 -> -0.12 | B34: 1 | C34: =_xlfn.NORM.DIST(A34-0.0025, Asset_Stats!$D$2, Asset_Stats!$D$4, FALSE) * 0.06 * 120 -> 7.7766085
A35: =A34+0.06 -> -0.06 | B35: 13 | C35: =_xlfn.NORM.DIST(A35-0.0025, Asset_Stats!$D$2, Asset_Stats!$D$4, FALSE) * 0.06 * 120 -> 24.776269
A36: =A35+0.06 -> 0 | B36: 39 | C36: =_xlfn.NORM.DIST(A36-0.0025, Asset_Stats!$D$2, Asset_Stats!$D$4, FALSE) * 0.06 * 120 -> 39.460051
A37: =A36+0.06 -> 0.06 | B37: 37 | C37: =_xlfn.NORM.DIST(A37-0.0025, Asset_Stats!$D$2, Asset_Stats!$D$4, FALSE) * 0.06 * 120 -> 31.41633
A38: =A37+0.06 -> 0.12 | B38: 21 | C38: =_xlfn.NORM.DIST(A38-0.0025, Asset_Stats!$D$2, Asset_Stats!$D$4, FALSE) * 0.06 * 120 -> 12.503435
A39: =A38+0.06 -> 0.18 | B39: 4 | C39: =_xlfn.NORM.DIST(A39-0.0025, Asset_Stats!$D$2, Asset_Stats!$D$4, FALSE) * 0.06 * 120 -> 2.4875928
A40: =A39+0.06 -> 0.24 | B40: 1 | C40: =_xlfn.NORM.DIST(A40-0.0025, Asset_Stats!$D$2, Asset_Stats!$D$4, FALSE) * 0.06 * 120 -> 0.24740319
...

Sheet Validation_A1
A1: Date | B1: xAsset1 | C1: HY-GAGG | D1: US Muni | E1: US Tbill 1-3yr | F1: Global AGG | G1: EM Bond | H1: TIPs | I1: Gold | J1: RollPred
A2: =Data!A2 -> 38016 | B2: =Data!B2 - Factors!AB4 -> 0.005534337 | C2: =Factors!N4 - Factors!E4 -> 0.012420118 | D2: =Factors!B4 -> 0.0045136227 | E2: =Factors!C4 -> 0.0021072108 | F2: =Factors!E4 -> 0.0037328896 | G2: =Factors!L4 -> 0.0051267546 | H2: =Factors!M4 -> 0.012326082 | I2: =Factors!Z4 -> -0.031291371
A3: =Data!A3 -> 38044 | B3: =Data!B3 - Factors!AB5 -> 0.0076974457 | C3: =Factors!N5 - Factors!E5 -> -0.0062488062 | D3: =Factors!B5 -> 0.014482164 | E3: =Factors!C5 -> 0.0050261565 | F3: =Factors!E5 -> 0.0051522151 | G3: =Factors!L5 -> 0.0034824821 | H3: =Factors!M5 -> 0.024775375 | I3: =Factors!Z5 -> -0.015654119 | K3: SUMMARY OUTPUT
A4: =Data!A4 -> 38077 | B4: =Data!B4 - Factors!AB6 -> 0.00359195 | C4: =Factors!N6 - Factors!E6 -> -0.0044051421 | D4: =Factors!B6 -> -0.0047764906 | E4: =Factors!C6 -> 0.0032149418 | F4: =Factors!E6 -> 0.011076524 | G4: =Factors!L6 -> 0.024958811 | H4: =Factors!M6 -> 0.017390173 | I4: =Factors!Z6 -> 0.076486179
A5: =Data!A5 -> 38107 | B5: =Data!B5 - Factors!AB7 -> -0.018594571 | C5: =Factors!N7 - Factors!E7 -> 0.029962729 | D5: =Factors!B7 -> -0.020876864 | E5: =Factors!C7 -> -0.010071723 | F5: =Factors!E7 -> -0.036564036 | G5: =Factors!L7 -> -0.054311023 | H5: =Factors!M7 -> -0.046496063 | I5: =Factors!Z7 -> -0.093094149 | K5: Regression Statistics
A6: =Data!A6 -> 38138 | B6: =Data!B6 - Factors!AB8 -> -0.0029775632 | C6: =Factors!N8 - Factors!E8 -> -0.02061187 | D6: =Factors!B8 -> -0.0022641617 | E6: =Factors!C8 -> -0.0011304661 | F6: =Factors!E8 -> 0.0049003612 | G6: =Factors!L8 -> -0.014827674 | H6: =Factors!M8 -> 0.016443736 | I6: =Factors!Z8 -> 0.022753717 | K6: Multiple R | L6: 0.8350451
A7: =Data!A7 -> 38168 | B7: =Data!B7 - Factors!AB9 -> 0.0081784614 | C7: =Factors!N9 - Factors!E9 -> 0.011604847 | D7: =Factors!B9 -> 0.0033728521 | E7: =Factors!C9 -> -0.00010288595 | F7: =Factors!E9 -> 0.002922566 | G7: =Factors!L9 -> 0.014683749 | H7: =Factors!M9 -> -0.0026148152 | I7: =Factors!Z9 -> -0.003286563 | K7: R Square | L7: 0.69730032
A8: =Data!A8 -> 38198 | B8: =Data!B8 - Factors!AB10 -> 0.0079909892 | C8: =Factors!N10 - Factors!E10 -> 0.013683916 | D8: =Factors!B10 -> 0.011548622 | E8: =Factors!C10 -> 0.0036528271 | F8: =Factors!E10 -> -0.0002074828 | G8: =Factors!L10 -> 0.029702254 | H8: =Factors!M10 -> 0.016134553 | I8: =Factors!Z10 -> -0.0081166772 | K8: Adjusted R Square | L8: 0.67838159
A9: =Data!A9 -> 38230 | B9: =Data!B9 - Factors!AB11 -> 0.01432793 | C9: =Factors!N11 - Factors!E11 -> -0.0037153097 | D9: =Factors!B11 -> 0.01810155 | E9: =Factors!C11 -> 0.0071252819 | F9: =Factors!E11 -> 0.021887267 | G9: =Factors!L11 -> 0.041283114 | H9: =Factors!M11 -> 0.025976512 | I9: =Factors!Z11 -> 0.048075694 | K9: Standard Error | L9: 0.004354312
A10: =Data!A10 -> 38260 | B10: =Data!B10 - Factors!AB12 -> 0.00031251778 | C10: =Factors!N12 - Factors!E12 -> 0.0021144631 | D10: =Factors!B12 -> 0.0037546187 | E10: =Factors!C12 -> -0.0008143737 | F10: =Factors!E12 -> 0.01181709 | G10: =Factors!L12 -> 0.016634612 | H10: =Factors!M12 -> 0.0015744976 | I10: =Factors!Z12 -> 0.020495303 | K10: Observations | L10: 120
A11: =Data!A11 -> 38289 | B11: =Data!B11 - Factors!AB13 -> 0.006845742 | C11: =Factors!N13 - Factors!E13 -> -0.0046737517 | D11: =Factors!B13 -> 0.0067472552 | E11: =Factors!C13 -> 0.0031582701 | F11: =Factors!E13 -> 0.023953957 | G11: =Factors!L13 -> 0.016096913 | H11: =Factors!M13 -> 0.014200355 | I11: =Factors!Z13 -> 0.02462642
A12: =Data!A12 -> 38321 | B12: =Data!B12 - Factors!AB14 -> -0.0038796692 | C12: =Factors!N14 - Factors!E14 -> -0.016092938 | D12: =Factors!B14 -> -0.0086422779 | E12: =Factors!C14 -> -0.0051287259 | F12: =Factors!E14 -> 0.026496979 | G12: =Factors!L14 -> 0.0069900376 | H12: =Factors!M14 -> -0.0070595322 | I12: =Factors!Z14 -> 0.05226928 | K12: ANOVA
A13: =Data!A13 -> 38352 | B13: =Data!B13 - Factors!AB15 -> 0.0051129046 | C13: =Factors!N15 - Factors!E15 -> -0.00024049779 | D13: =Factors!B15 -> 0.0097161351 | E13: =Factors!C15 -> 0.0021437321 | F13: =Factors!E15 -> 0.015321934 | G13: =Factors!L15 -> 0.025041357 | H13: =Factors!M15 -> 0.013768153 | I13: =Factors!Z15 -> -0.027719259 | L13: df | M13: SS | N13: MS | O13: F | P13: Significance F
A14: =Data!A14 -> 38383 | B14: =Data!B14 - Factors!AB16 -> 0.0036364555 | C14: =Factors!N16 - Factors!E16 -> 0.0095053028 | D14: =Factors!B16 -> 0.0052499575 | E14: =Factors!C16 -> -0.00040745645 | F14: =Factors!E16 -> -0.010524264 | G14: =Factors!L16 -> 0.0062656245 | H14: =Factors!M16 -> 0.0054076539 | I14: =Factors!Z16 -> -0.036150074 | K14: Regression | L14: 7 | M14: 0.0048917586 | N14: 0.00069882265 | O14: 36.857671 | P14: 2.7273079e-26
A15: =Data!A15 -> 38411 | B15: =Data!B15 - Factors!AB17 -> -0.0062576928 | C15: =Factors!N17 - Factors!E17 -> 0.012380416 | D15: =Factors!B17 -> -0.0046337596 | E15: =Factors!C17 -> -0.0024457352 | F15: =Factors!E17 -> 0.0019035659 | G15: =Factors!L17 -> 0.0066668763 | H15: =Factors!M17 -> -0.0071714246 | I15: =Factors!Z17 -> 0.030880265 | K15: Residual | L15: 112 | M15: 0.0021235237 | N15: 1.8960033e-05
A16: =Data!A16 -> 38442 | B16: =Data!B16 - Factors!AB18 -> -0.0041361703 | C16: =Factors!N18 - Factors!E18 -> -0.015214777 | D16: =Factors!B18 -> -0.0070461486 | E16: =Factors!C18 -> -5.107774e-05 | F16: =Factors!E18 -> -0.012098137 | G16: =Factors!L18 -> -0.025459998 | H16: =Factors!M18 -> -0.0044377509 | I16: =Factors!Z18 -> -0.016756571 | K16: Total | L16: 119 | M16: 0.0070152822
A17: =Data!A17 -> 38471 | B17: =Data!B17 - Factors!AB19 -> 0.0088541607 | C17: =Factors!N19 - Factors!E19 -> -0.023814428 | D17: =Factors!B19 -> 0.014397938 | E17: =Factors!C19 -> 0.0058231598 | F17: =Factors!E19 -> 0.013086726 | G17: =Factors!L19 -> 0.015771253 | H17: =Factors!M19 -> 0.025283828 | I17: =Factors!Z19 -> 0.014100619
A18: =Data!A18 -> 38503 | B18: =Data!B18 - Factors!AB20 -> 0.0054878374 | C18: =Factors!N20 - Factors!E20 -> 0.031300321 | D18: =Factors!B20 -> 0.0050434595 | E18: =Factors!C20 -> 0.0038088467 | F18: =Factors!E20 -> -0.013397377 | G18: =Factors!L20 -> 0.029916688 | H18: =Factors!M20 -> 0.0069189282 | I18: =Factors!Z20 -> -0.03945763 | L18: Coefficients | M18: Standard Error | N18: t Stat | O18: P-value | P18: Lower 95% | Q18: Upper 95% | R18: Lower 95.0% | S18: Upper 95.0%
A19: =Data!A19 -> 38533 | B19: =Data!B19 - Factors!AB21 -> 0.0013617324 | C19: =Factors!N21 - Factors!E21 -> 0.023515645 | D19: =Factors!B21 -> 0.0053472183 | E19: =Factors!C21 -> 0.0018719012 | F19: =Factors!E21 -> -0.0044845893 | G19: =Factors!L21 -> 0.017771786 | H19: =Factors!M21 -> 0.0036562031 | I19: =Factors!Z21 -> 0.043738766 | K19: Intercept | L19: 0.00014878997 | M19: 0.00050931758 | N19: 0.29213594 | O19: 0.77072315 | P19: -0.00086035753 | Q19: 0.0011579375 | R19: -0.00086035753 | S19: 0.0011579375
A20: =Data!A20 -> 38562 | B20: =Data!B20 - Factors!AB22 -> -0.0074498679 | C20: =Factors!N22 - Factors!E22 -> 0.023707031 | D20: =Factors!B22 -> -0.0058462084 | E20: =Factors!C22 -> -0.0029793466 | F20: =Factors!E22 -> -0.0080068466 | G20: =Factors!L22 -> -0.0024686898 | H20: =Factors!M22 -> -0.018193158 | I20: =Factors!Z22 -> -0.013088404 | K20: HY-GAGG | L20: -0.092828826 | M20: 0.024534566 | N20: -3.7835936 | O20: 0.00024995833 | P20: -0.14144092 | Q20: -0.044216729 | R20: -0.14144092 | S20: -0.044216729
A21: =Data!A21 -> 38595 | B21: =Data!B21 - Factors!AB23 -> 0.0060719039 | C21: =Factors!N23 - Factors!E23 -> -0.012839365 | D21: =Factors!B23 -> 0.0088760151 | E21: =Factors!C23 -> 0.006280389 | F21: =Factors!E23 -> 0.016459134 | G21: =Factors!L23 -> 0.019406048 | H21: =Factors!M23 -> 0.024976539 | I21: =Factors!Z23 -> 0.012563983 | K21: US Muni | L21: 0.12690855 | M21: 0.048911177 | N21: 2.5946739 | O21: 0.010734358 | P21: 0.029997324 | Q21: 0.22381978 | R21: 0.029997324 | S21: 0.22381978
A22: =Data!A22 -> 38625 | B22: =Data!B22 - Factors!AB24 -> -0.0082182653 | C22: =Factors!N24 - Factors!E24 -> 0.0059054787 | D22: =Factors!B24 -> -0.0053323723 | E22: =Factors!C24 -> -0.0026676062 | F22: =Factors!E24 -> -0.015920275 | G22: =Factors!L24 -> 0.016904995 | H22: =Factors!M24 -> -0.0052538911 | I22: =Factors!Z24 -> 0.078354779 | K22: US Tbill 1-3yr | L22: 0.48595859 | M22: 0.14644118 | N22: 3.3184559 | O22: 0.0012215802 | P22: 0.19580417 | Q22: 0.77611301 | R22: 0.19580417 | S22: 0.77611301
A23: =Data!A23 -> 38656 | B23: =Data!B23 - Factors!AB25 -> -0.0096210421 | C23: =Factors!N25 - Factors!E25 -> 0.0075918327 | D23: =Factors!B25 -> -0.005316902 | E23: =Factors!C25 -> -0.00020186727 | F23: =Factors!E25 -> -0.014886017 | G23: =Factors!L25 -> -0.014789799 | H23: =Factors!M25 -> -0.012573985 | I23: =Factors!Z25 -> -0.0087577243 | K23: Global AGG | L23: -0.076394898 | M23: 0.043089834 | N23: -1.7729216 | O23: 0.078960172 | P23: -0.16177188 | Q23: 0.0089820848 | R23: -0.16177188 | S23: 0.0089820848
A24: =Data!A24 -> 38686 | B24: =Data!B24 - Factors!AB26 -> 0.00019473398 | C24: =Factors!N26 - Factors!E26 -> 0.011922581 | D24: =Factors!B26 -> 0.004390689 | E24: =Factors!C26 -> 0.0032810055 | F24: =Factors!E26 -> -0.0070979041 | G24: =Factors!L26 -> 0.015277778 | H24: =Factors!M26 -> 0.0019717785 | I24: =Factors!Z26 -> 0.059953997 | K24: EM Bond | L24: 0.15283301 | M24: 0.032833378 | N24: 4.6548063 | O24: 8.9622061e-06 | P24: 0.087777884 | Q24: 0.21788814 | R24: 0.087777884 | S24: 0.21788814
A25: =Data!A25 -> 38716 | B25: =Data!B25 - Factors!AB27 -> 0.0065581799 | C25: =Factors!N27 - Factors!E27 -> -0.00071723125 | D25: =Factors!B27 -> 0.0068721605 | E25: =Factors!C27 -> 0.0038740189 | F25: =Factors!E27 -> 0.0098715137 | G25: =Factors!L27 -> 0.018482405 | H25: =Factors!M27 -> 0.0084798523 | I25: =Factors!Z27 -> 0.048511398 | K25: TIPs | L25: 0.10232754 | M25: 0.031273573 | N25: 3.272013 | O25: 0.00142002 | P25: 0.040362962 | Q25: 0.16429211 | R25: 0.040362962 | S25: 0.16429211
A26: =Data!A26 -> 38748 | B26: =Data!B26 - Factors!AB28 -> 4.4318948e-06 | C26: =Factors!N28 - Factors!E28 -> 0.0032352419 | D26: =Factors!B28 -> 0.0028999352 | E26: =Factors!C28 -> 0.0015035333 | F26: =Factors!E28 -> 0.012614298 | G26: =Factors!L28 -> 0.011974166 | H26: =Factors!M28 -> 0.00078054042 | I26: =Factors!Z28 -> 0.10038685 | K26: Gold | L26: -0.0056226851 | M26: 0.0086418469 | N26: -0.65063466 | O26: 0.51661488 | P26: -0.022745397 | Q26: 0.011500027 | R26: -0.022745397 | S26: 0.011500027
A27: =Data!A27 -> 38776 | B27: =Data!B27 - Factors!AB29 -> 0.0014557254 | C27: =Factors!N29 - Factors!E29 -> 0.0098689223 | D27: =Factors!B29 -> 0.0040444707 | E27: =Factors!C29 -> 0.00075063804 | F27: =Factors!E29 -> -0.0035465658 | G27: =Factors!L29 -> 0.022224732 | H27: =Factors!M29 -> -0.0034033381 | I27: =Factors!Z29 -> -0.01291967
A28: =Data!A28 -> 38807 | B28: =Data!B28 - Factors!AB30 -> -0.012312888 | C28: =Factors!N30 - Factors!E30 -> 0.016163657 | D28: =Factors!B30 -> -0.0063508292 | E28: =Factors!C30 -> 0.00120012 | F28: =Factors!E30 -> -0.0099131724 | G28: =Factors!L30 -> -0.018978949 | H28: =Factors!M30 -> -0.020532449 | I28: =Factors!Z30 -> 0.039355356
A29: =Data!A29 -> 38835 | B29: =Data!B29 - Factors!AB31 -> -0.0037051408 | C29: =Factors!N31 - Factors!E31 -> -0.012502969 | D29: =Factors!B31 -> 1.3389487e-05 | E29: =Factors!C31 -> 0.0030965937 | F29: =Factors!E31 -> 0.018928887 | G29: =Factors!L31 -> -0.00084480865 | H29: =Factors!M31 -> 0.00010169098 | I29: =Factors!Z31 -> 0.12125418
A30: =Data!A30 -> 38868 | B30: =Data!B30 - Factors!AB32 -> -0.005874578 | C30: =Factors!N32 - Factors!E32 -> -0.013529189 | D30: =Factors!B32 -> 0.004853624 | E30: =Factors!C32 -> 0.0014439355 | F30: =Factors!E32 -> 0.012897983 | G30: =Factors!L32 -> -0.02048984 | H30: =Factors!M32 -> 0.0021352933 | I30: =Factors!Z32 -> -0.014088811
A31: =Data!A31 -> 38898 | B31: =Data!B31 - Factors!AB33 -> -0.002027934 | C31: =Factors!N33 - Factors!E33 -> 0.0041536738 | D31: =Factors!B33 -> -0.0036248131 | E31: =Factors!C33 -> 0.0017898871 | F31: =Factors!E33 -> -0.0079451696 | G31: =Factors!L33 -> -5.7547333e-05 | H31: =Factors!M33 -> 0.0035947239 | I31: =Factors!Z33 -> -0.045489771
A32: =Data!A32 -> 38929 | B32: =Data!B32 - Factors!AB34 -> 0.010264381 | C32: =Factors!N34 - Factors!E34 -> 0.00070743003 | D32: =Factors!B34 -> 0.010644481 | E32: =Factors!C34 -> 0.0074941684 | F32: =Factors!E34 -> 0.0099619177 | G32: =Factors!L34 -> 0.032717541 | H32: =Factors!M34 -> 0.016696034 | I32: =Factors!Z34 -> 0.033936835
A33: =Data!A33 -> 38960 | B33: =Data!B33 - Factors!AB35 -> 0.010262188 | C33: =Factors!N35 - Factors!E35 -> 0.0046252147 | D33: =Factors!B35 -> 0.013140651 | E33: =Factors!C35 -> 0.0071428571 | F33: =Factors!E35 -> 0.011555066 | G33: =Factors!L35 -> 0.026024687 | H33: =Factors!M35 -> 0.018765804 | I33: =Factors!Z35 -> -0.014840989
A34: =Data!A34 -> 38989 | B34: =Data!B34 - Factors!AB36 -> 0.0026278673 | C34: =Factors!N36 - Factors!E36 -> 0.013228492 | D34: =Factors!B36 -> 0.0063670591 | E34: =Factors!C36 -> 0.00513573 | F34: =Factors!E36 -> -7.4683066e-05 | G34: =Factors!L36 -> 0.0055943296 | H34: =Factors!M36 -> 0.0025169072 | I34: =Factors!Z36 -> -0.046229874
A35: =Data!A35 -> 39021 | B35: =Data!B35 - Factors!AB37 -> 0.0033539067 | C35: =Factors!N37 - Factors!E37 -> 0.0049282704 | D35: =Factors!B37 -> 0.0049471146 | E35: =Factors!C37 -> 0.0038442822 | F35: =Factors!E37 -> 0.0096735856 | G35: =Factors!L37 -> 0.018553026 | H35: =Factors!M37 -> -0.0015995438 | I35: =Factors!Z37 -> 0.013872639
A36: =Data!A36 -> 39051 | B36: =Data!B36 - Factors!AB38 -> 0.0073057981 | C36: =Factors!N38 - Factors!E38 -> -0.0083921078 | D36: =Factors!B38 -> 0.0063279162 | E36: =Factors!C38 -> 0.0051383974 | F36: =Factors!E38 -> 0.024354469 | G36: =Factors!L38 -> 0.012673666 | H36: =Factors!M38 -> 0.012412842 | I36: =Factors!Z38 -> 0.068249258
A37: =Data!A37 -> 39080 | B37: =Data!B37 - Factors!AB39 -> -0.0070648521 | C37: =Factors!N39 - Factors!E39 -> 0.024265253 | D37: =Factors!B39 -> -0.0028721038 | E37: =Factors!C39 -> 4.8227634e-05 | F37: =Factors!E39 -> -0.013256313 | G37: =Factors!L39 -> 0.0066502592 | H37: =Factors!M39 -> -0.024954762 | I37: =Factors!Z39 -> -0.017438272
A38: =Data!A38 -> 39113 | B38: =Data!B38 - Factors!AB40 -> -0.0034834649 | C38: =Factors!N40 - Factors!E40 -> 0.020572221 | D38: =Factors!B40 -> -0.002430921 | E38: =Factors!C40 -> 0.0020736883 | F38: =Factors!E40 -> -0.0098284605 | G38: =Factors!L40 -> -0.0030430712 | H38: =Factors!M40 -> 0.0023074318 | I38: =Factors!Z40 -> 0.025914874 | J38: {=TREND(B2:B37, C2:I37, C38:I38, TRUE)} -> -0.0025678599
A39: =Data!A39 -> 39141 | B39: =Data!B39 - Factors!AB41 -> 0.0085567023 | C39: =Factors!N41 - Factors!E41 -> -0.0066493112 | D39: =Factors!B41 -> 0.011358545 | E39: =Factors!C41 -> 0.0080850859 | F39: =Factors!E41 -> 0.020578466 | G39: =Factors!L41 -> 0.017166262 | H39: =Factors!M41 -> 0.022753673 | I39: =Factors!Z41 -> 0.024724434 | J39: {=TREND(B3:B38, C3:I38, C39:I39, TRUE)} -> 0.0088591439
A40: =Data!A40 -> 39171 | B40: =Data!B40 - Factors!AB42 -> -0.0018456249 | C40: =Factors!N42 - Factors!E42 -> -4.1273382e-05 | D40: =Factors!B42 -> -0.00046020954 | E40: =Factors!C42 -> 0.0038669022 | F40: =Factors!E42 -> 0.0023638205 | G40: =Factors!L42 -> 0.0097463387 | H40: =Factors!M42 -> 0.0030425056 | I40: =Factors!Z42 -> -0.0083065661 | J40: {=TREND(B4:B39, C4:I39, C40:I40, TRUE)} -> 0.0011536081
...

Sheet A1
A1: Date | B1: xAsset1 | C1: US AGG | D1: EM Bond | E1: Credit Spread | G1: Predicted | H1: Residual | I1: Resid_ex0809 | J1: xAsset_ex0809 | L1: Factor | M1: R^2 aux | N1: VIF
A2: =Data!A2 -> 38016 | B2: =Data!B2 - Factors!AB4 -> 0.005534337 | C2: =Factors!D4 -> 0.0080453023 | D2: =Factors!L4 -> 0.0051267546 | E2: =Factors!N4 - Factors!D4 -> 0.0081077053 | L2: US AGG | M2: =INDEX(LINEST(C2:C121, D2:E121, TRUE, TRUE), 3, 1) -> 0.69636819 | N2: =1/(1-M2) -> 3.2934626
A3: =Data!A3 -> 38044 | B3: =Data!B3 - Factors!AB5 -> 0.0076974457 | C3: =Factors!D5 -> 0.010824142 | D3: =Factors!L5 -> 0.0034824821 | E3: =Factors!N5 - Factors!D5 -> -0.011920733 | L3: EM Bond | M3: =INDEX(LINEST(D2:D121, CHOOSE({1,2}, C2:C121, E2:E121), TRUE, TRUE), 3, 1) -> 0.79122174 | N3: =1/(1-M3) -> 4.7897707
A4: =Data!A4 -> 38077 | B4: =Data!B4 - Factors!AB6 -> 0.00359195 | C4: =Factors!D6 -> 0.0074889868 | D4: =Factors!L6 -> 0.024958811 | E4: =Factors!N6 - Factors!D6 -> -0.00081760495 | L4: Credit Spread | M4: =INDEX(LINEST(E2:E121, C2:D121, TRUE, TRUE), 3, 1) -> 0.6418213 | N4: =1/(1-M4) -> 2.7919025
A5: =Data!A5 -> 38107 | B5: =Data!B5 - Factors!AB7 -> -0.018594571 | C5: =Factors!D7 -> -0.026016616 | D5: =Factors!L7 -> -0.054311023 | E5: =Factors!N7 - Factors!D7 -> 0.019415308 | G5: SUMMARY OUTPUT | Q5: SUMMARY OUTPUT
A6: =Data!A6 -> 38138 | B6: =Data!B6 - Factors!AB8 -> -0.0029775632 | C6: =Factors!D8 -> -0.0040058707 | D6: =Factors!L8 -> -0.014827674 | E6: =Factors!N8 - Factors!D8 -> -0.011705638
A7: =Data!A7 -> 38168 | B7: =Data!B7 - Factors!AB9 -> 0.0081784614 | C7: =Factors!D9 -> 0.0056515785 | D7: =Factors!L9 -> 0.014683749 | E7: =Factors!N9 - Factors!D9 -> 0.0088758343 | G7: Regression Statistics | Q7: Regression Statistics
A8: =Data!A8 -> 38198 | B8: =Data!B8 - Factors!AB10 -> 0.0079909892 | C8: =Factors!D10 -> 0.009912255 | D8: =Factors!L10 -> 0.029702254 | E8: =Factors!N10 - Factors!D10 -> 0.0035641781 | G8: Multiple R | H8: 0.90414707 | N8: corr(US AGG, US Tbill) = 0.6011 | Q8: Multiple R | R8: 0.90414418
A9: =Data!A9 -> 38230 | B9: =Data!B9 - Factors!AB11 -> 0.01432793 | C9: =Factors!D11 -> 0.019075174 | D9: =Factors!L11 -> 0.041283114 | E9: =Factors!N11 - Factors!D11 -> -0.00090321685 | G9: R Square | H9: 0.81748192 | Q9: R Square | R9: 0.8174767
A10: =Data!A10 -> 38260 | B10: =Data!B10 - Factors!AB12 -> 0.00031251778 | C10: =Factors!D12 -> 0.0027134997 | D10: =Factors!L12 -> 0.016634612 | E10: =Factors!N12 - Factors!D12 -> 0.011218053 | G10: Adjusted R Square | H10: 0.81113346 | Q10: Adjusted R Square | R10: 0.81275627
A11: =Data!A11 -> 38289 | B11: =Data!B11 - Factors!AB13 -> 0.006845742 | C11: =Factors!D13 -> 0.0083857442 | D11: =Factors!L13 -> 0.016096913 | E11: =Factors!N13 - Factors!D13 -> 0.010894461 | G11: Standard Error | H11: 0.0033367725 | Q11: Standard Error | R11: 0.0033224063
A12: =Data!A12 -> 38321 | B12: =Data!B12 - Factors!AB14 -> -0.0038796692 | C12: =Factors!D14 -> -0.0079764104 | D12: =Factors!L14 -> 0.0069900376 | E12: =Factors!N14 - Factors!D14 -> 0.018380451 | G12: Observations | H12: 120 | Q12: Observations | R12: 120
A13: =Data!A13 -> 38352 | B13: =Data!B13 - Factors!AB15 -> 0.0051129046 | C13: =Factors!D15 -> 0.0092011222 | D13: =Factors!L15 -> 0.025041357 | E13: =Factors!N15 - Factors!D15 -> 0.0058803136
A14: =Data!A14 -> 38383 | B14: =Data!B14 - Factors!AB16 -> 0.0036364555 | C14: =Factors!D16 -> 0.0062794738 | D14: =Factors!L16 -> 0.0062656245 | E14: =Factors!N16 - Factors!D16 -> -0.0072984348 | G14: ANOVA | O14: drop tbill | Q14: ANOVA
A15: =Data!A15 -> 38411 | B15: =Data!B15 - Factors!AB17 -> -0.0062576928 | C15: =Factors!D17 -> -0.0059031974 | D15: =Factors!L17 -> 0.0066668763 | E15: =Factors!N17 - Factors!D17 -> 0.020187179 | H15: df | I15: SS | J15: MS | K15: F | L15: Significance F | R15: df | S15: SS | T15: MS | U15: F | V15: Significance F
A16: =Data!A16 -> 38442 | B16: =Data!B16 - Factors!AB18 -> -0.0041361703 | C16: =Factors!D18 -> -0.0051360091 | D16: =Factors!L18 -> -0.025459998 | E16: =Factors!N18 - Factors!D18 -> -0.022176904 | G16: Regression | H16: 4 | I16: 0.0057348664 | J16: 0.0014337166 | K16: 128.76864 | L16: 1.6083377e-41 | Q16: Regression | R16: 3 | S16: 0.0057348298 | T16: 0.0019116099 | U16: 173.17843 | V16: 1.12326e-42
A17: =Data!A17 -> 38471 | B17: =Data!B17 - Factors!AB19 -> 0.0088541607 | C17: =Factors!D19 -> 0.01353396 | D17: =Factors!L19 -> 0.015771253 | E17: =Factors!N19 - Factors!D19 -> -0.024261662 | G17: Residual | H17: 115 | I17: 0.0012804158 | J17: 1.1134051e-05 | Q17: Residual | R17: 116 | S17: 0.0012804525 | T17: 1.1038383e-05
A18: =Data!A18 -> 38503 | B18: =Data!B18 - Factors!AB20 -> 0.0054878374 | C18: =Factors!D20 -> 0.010818747 | D18: =Factors!L20 -> 0.029916688 | E18: =Factors!N20 - Factors!D20 -> 0.0070841965 | G18: Total | H18: 119 | I18: 0.0070152822 | Q18: Total | R18: 119 | S18: 0.0070152822
A19: =Data!A19 -> 38533 | B19: =Data!B19 - Factors!AB21 -> 0.0013617324 | C19: =Factors!D21 -> 0.0054529078 | D19: =Factors!L21 -> 0.017771786 | E19: =Factors!N21 - Factors!D21 -> 0.013578147
A20: =Data!A20 -> 38562 | B20: =Data!B20 - Factors!AB22 -> -0.0074498679 | C20: =Factors!D22 -> -0.0090953845 | D20: =Factors!L22 -> -0.0024686898 | E20: =Factors!N22 - Factors!D22 -> 0.024795569 | H20: Coefficients | I20: Standard Error | J20: t Stat | K20: P-value | L20: Lower 95% | M20: Upper 95% | N20: Lower 95.0% | O20: Upper 95.0% | R20: Coefficients | S20: Standard Error | T20: t Stat | U20: P-value | V20: Lower 95% | W20: Upper 95% | X20: Lower 95.0% | Y20: Upper 95.0%
A21: =Data!A21 -> 38595 | B21: =Data!B21 - Factors!AB23 -> 0.0060719039 | C21: =Factors!D23 -> 0.012811324 | D21: =Factors!L23 -> 0.019406048 | E21: =Factors!N23 - Factors!D23 -> -0.0091915546 | G21: Intercept | H21: 0.0001073372 | I21: 0.00037015553 | J21: 0.28997864 | K21: 0.77235479 | L21: -0.00062586966 | M21: 0.00084054406 | N21: -0.00062586966 | O21: 0.00084054406 | Q21: Intercept | R21: 0.00011659258 | S21: 0.00033168542 | T21: 0.35151554 | U21: 0.72583931 | V21: -0.00054035218 | W21: 0.00077353734 | X21: -0.00054035218 | Y21: 0.00077353734
A22: =Data!A22 -> 38625 | B22: =Data!B22 - Factors!AB24 -> -0.0082182653 | C22: =Factors!D24 -> -0.010301154 | D22: =Factors!L24 -> 0.016904995 | E22: =Factors!N24 - Factors!D24 -> 0.00028635718 | G22: US AGG | H22: 0.59268256 | I22: 0.06612289 | J22: 8.9633493 | K22: 6.7272228e-15 | L22: 0.46170584 | M22: 0.72365928 | N22: 0.46170584 | O22: 0.72365928 | Q22: US AGG | R22: 0.59460301 | S22: 0.056770538 | T22: 10.473796 | U22: 1.800181e-18 | V22: 0.48216181 | W22: 0.70704422 | X22: 0.48216181 | Y22: 0.70704422
A23: =Data!A23 -> 38656 | B23: =Data!B23 - Factors!AB25 -> -0.0096210421 | C23: =Factors!D25 -> -0.007913938 | D23: =Factors!L25 -> -0.014789799 | E23: =Factors!N25 - Factors!D25 -> 0.00061975345 | G23: US Tbill 1-3yr | H23: 0.0065937106 | I23: 0.11497663 | J23: 0.057348268 | K23: 0.9543673 | L23: -0.22115287 | M23: 0.23434029 | N23: -0.22115287 | O23: 0.23434029 | Q23: EM Bond | R23: 0.052414433 | S23: 0.025722588 | T23: 2.0376812 | U23: 0.043856833 | V23: 0.0014676064 | W23: 0.10336126 | X23: 0.0014676064 | Y23: 0.10336126
A24: =Data!A24 -> 38686 | B24: =Data!B24 - Factors!AB26 -> 0.00019473398 | C24: =Factors!D26 -> 0.0044226044 | D24: =Factors!L26 -> 0.015277778 | E24: =Factors!N26 - Factors!D26 -> 0.0004020722 | G24: EM Bond | H24: 0.05259625 | I24: 0.026027627 | J24: 2.0207854 | K24: 0.04562502 | L24: 0.0010405298 | M24: 0.10415197 | N24: 0.0010405298 | O24: 0.10415197 | Q24: Credit Spread | R24: -0.069793958 | S24: 0.017599311 | T24: -3.965721 | U24: 0.00012701342 | V24: -0.10465161 | W24: -0.034936304 | X24: -0.10465161 | Y24: -0.034936304
A25: =Data!A25 -> 38716 | B25: =Data!B25 - Factors!AB27 -> 0.0065581799 | C25: =Factors!D27 -> 0.0095075016 | D25: =Factors!L27 -> 0.018482405 | E25: =Factors!N27 - Factors!D27 -> -0.00035321919 | G25: Credit Spread | H25: -0.069456336 | I25: 0.018630066 | J25: -3.7281852 | K25: 0.00030084912 | L25: -0.10635891 | M25: -0.032553761 | N25: -0.10635891 | O25: -0.032553761
A26: =Data!A26 -> 38748 | B26: =Data!B26 - Factors!AB28 -> 4.4318948e-06 | C26: =Factors!D28 -> 5.6540071e-05 | D26: =Factors!L28 -> 0.011974166 | E26: =Factors!N28 - Factors!D28 -> 0.015793
A27: =Data!A27 -> 38776 | B27: =Data!B27 - Factors!AB29 -> 0.0014557254 | C27: =Factors!D29 -> 0.0033195222 | D27: =Factors!L29 -> 0.022224732 | E27: =Factors!N29 - Factors!D29 -> 0.0030028343
